2024-05-09 16:12:40,428 FILE: creds.py IN: create_new_token MESSAGE: Ошибка получения iam_token: HTTPConnectionPool(host='169.254.169.254', port=80): Max retries exceeded with url: /computeMetadata/v1/instance/service-accounts/default/token (Caused by ConnectTimeoutError(<urllib3.connection.HTTPConnection object at 0x000001F77A249910>, 'Connection to 169.254.169.254 timed out. (connect timeout=None)'))
2024-05-09 16:13:03,170 FILE: creds.py IN: create_new_token MESSAGE: Ошибка получения iam_token: HTTPConnectionPool(host='169.254.169.254', port=80): Max retries exceeded with url: /computeMetadata/v1/instance/service-accounts/default/token (Caused by ConnectTimeoutError(<urllib3.connection.HTTPConnection object at 0x000001F77A25A0D0>, 'Connection to 169.254.169.254 timed out. (connect timeout=None)'))
2024-05-09 16:13:25,346 FILE: creds.py IN: create_new_token MESSAGE: Ошибка получения iam_token: HTTPConnectionPool(host='169.254.169.254', port=80): Max retries exceeded with url: /computeMetadata/v1/instance/service-accounts/default/token (Caused by ConnectTimeoutError(<urllib3.connection.HTTPConnection object at 0x000001F77A259D90>, 'Connection to 169.254.169.254 timed out. (connect timeout=None)'))
2024-05-09 16:13:48,231 FILE: creds.py IN: create_new_token MESSAGE: Ошибка получения iam_token: HTTPConnectionPool(host='169.254.169.254', port=80): Max retries exceeded with url: /computeMetadata/v1/instance/service-accounts/default/token (Caused by ConnectTimeoutError(<urllib3.connection.HTTPConnection object at 0x000001F77A24AC50>, 'Connection to 169.254.169.254 timed out. (connect timeout=None)'))
2024-05-09 16:14:10,406 FILE: creds.py IN: create_new_token MESSAGE: Ошибка получения iam_token: HTTPConnectionPool(host='169.254.169.254', port=80): Max retries exceeded with url: /computeMetadata/v1/instance/service-accounts/default/token (Caused by ConnectTimeoutError(<urllib3.connection.HTTPConnection object at 0x000001F77A24BC90>, 'Connection to 169.254.169.254 timed out. (connect timeout=None)'))
2024-05-09 16:19:48,918 FILE: creds.py IN: create_new_token MESSAGE: Ошибка получения iam_token: HTTPConnectionPool(host='169.254.169.254', port=80): Max retries exceeded with url: /computeMetadata/v1/instance/service-accounts/default/token (Caused by ConnectTimeoutError(<urllib3.connection.HTTPConnection object at 0x000001F77A248B90>, 'Connection to 169.254.169.254 timed out. (connect timeout=None)'))
